{
	"header": {
		"line": "CVE-2019-3498 (In Django 1.11.x before 1.11.18, 2.0.x before 2.0.10, and 2.1.x before ...)",
		"name": "CVE-2019-3498",
		"description": "(In Django 1.11.x before 1.11.18, 2.0.x before 2.0.10, and 2.1.x before ...)"
	},
	"annotations": [
		{
			"line": "\t{DSA-4363-1 DLA-1629-1}",
			"type": "xref",
			"bugs": [
				"DSA-4363-1",
				"DLA-1629-1"
			]
		},
		{
			"line": "\t- python-django 1:1.11.18-1 (bug #918230)",
			"type": "package",
			"package": "python-django",
			"kind": "fixed",
			"version": "1:1.11.18-1",
			"flags": [
				{
					"bug": 918230
				}
			]
		},
		{
			"line": "\tNOTE: https://www.djangoproject.com/weblog/2019/jan/04/security-releases/",
			"type": "NOTE",
			"description": "https://www.djangoproject.com/weblog/2019/jan/04/security-releases/"
		},
		{
			"line": "\tNOTE: https://github.com/django/django/commit/1cd00fcf52d089ef0fe03beabd05d59df8ea052a (1.11.x)",
			"type": "NOTE",
			"description": "https://github.com/django/django/commit/1cd00fcf52d089ef0fe03beabd05d59df8ea052a (1.11.x)"
		},
		{
			"line": "\tNOTE: https://github.com/django/django/commit/64d2396e83aedba3fcc84ca40f23fbd22f0b9b5b (2.1.x)",
			"type": "NOTE",
			"description": "https://github.com/django/django/commit/64d2396e83aedba3fcc84ca40f23fbd22f0b9b5b (2.1.x)"
		}
	]
}
