{
	"header": {
		"line": "CVE-2018-14612 (An issue was discovered in the Linux kernel through 4.17.10. There is  ...)",
		"name": "CVE-2018-14612",
		"description": "(An issue was discovered in the Linux kernel through 4.17.10. There is  ...)"
	},
	"annotations": [
		{
			"line": "\t{DLA-2241-1 DLA-1715-1}",
			"type": "xref",
			"bugs": [
				"DLA-2241-1",
				"DLA-1715-1"
			]
		},
		{
			"line": "\t- linux 4.18.8-1",
			"type": "package",
			"package": "linux",
			"kind": "fixed",
			"version": "4.18.8-1"
		},
		{
			"line": "\t[stretch] - linux 4.9.144-1",
			"type": "package",
			"release": "stretch",
			"package": "linux",
			"kind": "fixed",
			"version": "4.9.144-1"
		},
		{
			"line": "\tNOTE: https://bugzilla.kernel.org/show_bug.cgi?id=199847",
			"type": "NOTE",
			"description": "https://bugzilla.kernel.org/show_bug.cgi?id=199847"
		},
		{
			"line": "\tNOTE: https://patchwork.kernel.org/patch/10503403/",
			"type": "NOTE",
			"description": "https://patchwork.kernel.org/patch/10503403/"
		},
		{
			"line": "\tNOTE: https://patchwork.kernel.org/patch/10503413/",
			"type": "NOTE",
			"description": "https://patchwork.kernel.org/patch/10503413/"
		}
	]
}
