{
	"header": {
		"line": "CVE-2022-26280 (Libarchive v3.6.0 was discovered to contain an out-of-bounds read via  ...)",
		"name": "CVE-2022-26280",
		"description": "(Libarchive v3.6.0 was discovered to contain an out-of-bounds read via  ...)"
	},
	"annotations": [
		{
			"line": "\t{DLA-3950-1}",
			"type": "xref",
			"bugs": [
				"DLA-3950-1"
			]
		},
		{
			"line": "\t- libarchive 3.6.2-1 (bug #1008953)",
			"type": "package",
			"package": "libarchive",
			"kind": "fixed",
			"version": "3.6.2-1",
			"flags": [
				{
					"bug": 1008953
				}
			]
		},
		{
			"line": "\t[buster] - libarchive <not-affected> (Vulnerable code not present)",
			"type": "package",
			"release": "buster",
			"package": "libarchive",
			"kind": "not-affected",
			"description": "Vulnerable code not present"
		},
		{
			"line": "\t[stretch] - libarchive <not-affected> (Vulnerable code not present)",
			"type": "package",
			"release": "stretch",
			"package": "libarchive",
			"kind": "not-affected",
			"description": "Vulnerable code not present"
		},
		{
			"line": "\tNOTE: https://github.com/libarchive/libarchive/issues/1672",
			"type": "NOTE",
			"description": "https://github.com/libarchive/libarchive/issues/1672"
		},
		{
			"line": "\tNOTE: Introduced by: https://github.com/libarchive/libarchive/commit/121035c83e18b70d3128e9ac966109ebedb7e516 (v3.4.0)",
			"type": "NOTE",
			"description": "Introduced by: https://github.com/libarchive/libarchive/commit/121035c83e18b70d3128e9ac966109ebedb7e516 (v3.4.0)"
		},
		{
			"line": "\tNOTE: Fixed by: https://github.com/libarchive/libarchive/commit/cfaa28168a07ea4a53276b63068f94fce37d6aff (v3.6.1)",
			"type": "NOTE",
			"description": "Fixed by: https://github.com/libarchive/libarchive/commit/cfaa28168a07ea4a53276b63068f94fce37d6aff (v3.6.1)"
		}
	]
}
