{
	"header": {
		"line": "CVE-2020-28493 (This affects the package jinja2 from 0.0.0 and before 2.11.3. The ReDo ...)",
		"name": "CVE-2020-28493",
		"description": "(This affects the package jinja2 from 0.0.0 and before 2.11.3. The ReDo ...)"
	},
	"annotations": [
		{
			"line": "\t- jinja2 2.11.3-1 (bug #982736)",
			"type": "package",
			"package": "jinja2",
			"kind": "fixed",
			"version": "2.11.3-1",
			"flags": [
				{
					"bug": 982736
				}
			]
		},
		{
			"line": "\t[buster] - jinja2 <no-dsa> (Minor issue)",
			"type": "package",
			"release": "buster",
			"package": "jinja2",
			"kind": "no-dsa",
			"description": "Minor issue"
		},
		{
			"line": "\t[stretch] - jinja2 <no-dsa> (Minor issue)",
			"type": "package",
			"release": "stretch",
			"package": "jinja2",
			"kind": "no-dsa",
			"description": "Minor issue"
		},
		{
			"line": "\tNOTE: https://github.com/pallets/jinja/pull/1343",
			"type": "NOTE",
			"description": "https://github.com/pallets/jinja/pull/1343"
		},
		{
			"line": "\tNOTE: https://snyk.io/vuln/SNYK-PYTHON-JINJA2-1012994",
			"type": "NOTE",
			"description": "https://snyk.io/vuln/SNYK-PYTHON-JINJA2-1012994"
		}
	]
}
